Workbook

Sheet INPUTS
A1: YOUR COMPANY INFORMATION
A2: COMPANY NAME | B2: Bradford Starke | D2: from website or SAM or Company InfoSheet
A3: SAM UEI | B3: L5L8ZT8Q74T8 | D3: from website or SAM or Company InfoSheet
A4: INDUSTRY | B4: STRATEGIC COMMUNICATIONS, MARKETING & BRANDING | D4: from website
A5: ABOUT US | B5: We help leaders achieve their goals through effective communications. Our team of experts combines experience and creativity to develop and execute custom strategies that accelerate success. We help leaders achieve their goals through effective communications. Our team of experts combines experience and creativity to develop and execute custom strategies that accelerate success. AWL Strategies supports a diverse list of clients, from start-ups to largefirms,non-profits,stateand local government, and Federal agencies. We are a GSA MAS contract holder and a certified Woman Owned Small Business in the following NAICS codes: 541611, 541613, 541820, 541511, 541990, 541990,561920. Marketing and Branding We align your business goals with branding and marketing goals to help you build credibility and trust with employees, customers, and strategic partners. Because leaders have their own personal brands to maintain, we provide coaching and content to help your voice and values resonate. Strategic Communications The internal is external, and vice versa. Your employees, partners and customers all want one thing: a story they can stand behind and stand for. We build strategies that start with purpose, not tactics-and drive outcomes, not just activities. | D5: from website
A6: YEARS CORP.EXP. | B6: 4 | D6: from website
A7: NUMBER EMPLOYEES | B7: 1 | D7: from website
A8: USING SUBCONTRACTORS | B8: uses Subcontractors | D8: from website
A9: PAST PERFORMANCE | D9: from website
A10: FROM RFQ / RFP
A11: AGENCY | B11: NASA | D11: From RFQ
A12: BASIS FOR AWARD | B12: Best Value | D12: From RFQ
A13: PROD OR SERVICE | B13: Services | D13: From RFQ
A14: NAICS CODE | B14: 541910 | D14: From RFQ
A15: TITLE | B15: Audience Research and Evaluation for the Earth Information Center Exhibition | D15: From RFQ
A16: SCOPE OF WORK (LONG) | B16: A. Introduction NASA Earth Science Division and National Museum of Natural History Partnership NASA Earth Science Division (ESD) maintains an extensive fleet of observing systems to collect global environmental data about the planet. ESD supports research with this data and associated models to characterize changes, understand trends, and improve predictions about the atmosphere, oceans, cryosphere, and land. ESD also supports direct applications of the data to improve decisions across a range of fields, such as water resources, agriculture, health, ecosystems management, and disasters. The Smithsonian’s National Museum of Natural History (NMNH), located on the National Mall in Washington, DC, is the most-visited natural history museum in the world with between 4 and 5 million on-site visitors and about 16 million online visitors annually. Its mission is “to better understand the natural world and our place in it.” The museum is regarded as a global leader in natural history collections, collections-based research, scientific discovery, and natural history exhibition. B. Scope of Work NASA envisions engaging with museum visitors – both on- and off-site – in new and innovative ways on this Exhibition. Audience research and evaluation will provide opportunities to test exhibition concepts and prototypes with visitors. A temporary exhibition space will include opportunities for testing content, engaging the public, and highlighting the exhibition development process. Efforts to talk with youth and their trusted adults should include, but reach beyond random sampling of individual, free-choice, on-site visitors in the galleries. Methods, such as creating focus groups of representatives of these audiences and reaching out to those organizations who organize youth tours or work with youth in community, may be considered. The contractor shall extend NASA’s reach and recruit participants and understand data that we do not have access to. The contractor shall include in their proposed plan and budget any incentives for those participating in the studies. The contractor shall provide professional, technical, and non-personal services to develop an audience research and evaluation plan for The EIC Exhibition. The execution of formative evaluation from July 2023 through summative evaluation by end of 2024 will be awarded as options as outlined below to be exercised pending funding and project scope evolution. Evaluation instruments, protocol, and appropriate incentives shall be developed by the contractor in collaboration with and approved by both NASA and NMNH. Both parties expect that the protocol required will depend on the elements being evaluated at each phase. For all evaluations design instruments will gather demographic data, including age, gender, racial/ethnic identification, and social composition of the visitor group. Throughout the implementation process, NASA will use the data, insights, and recommendations to inform decisions and adjust content to best meet the needs of the target audiences and actualize the project goals. NASA also plans to communicate salient findings from the audience research to stakeholders including NMNH leadership, NASA leadership, and the science community on a periodic basis. C. Tasks The contractor shall meet with the NASA Contracting Officer’s Technical Representative (COTR) designated in the contract and the NMNH project team, at a mutually convenient time within one week of the contract being awarded to discuss project goals, scheduling, audience research strategy, NASA/NMNH requirements (such as Human Subjects Research certification, Protection of Minors training, Internal Review Board and Privacy reviews), and NASA support. This work shall be divided into phases of work to be completed by the contractor in consultation with NASA. Throughout each phase of the contract, the contractor shall meet with the NASA COTR and/or team on at least a bi-weekly basis to determine next steps, coordinate work, and discuss interim findings. Base Contract Contractor shall create an evaluation plan and schedule for front-end and formative evaluation to support the Exhibition and companion virtual experience. Contactor shall design and conduct front-end and formative evaluation that includes target audience focus groups held online and on-site from July 2023 through November 2023 to provide baseline information about our target audiences, evaluate narrative and conceptual approaches, and prototype experience designs. Contractor shall design and conduct a summative evaluation of the Exhibition and companion virtual experience from December 2023 through February 2024. The summative evaluation will include various methodologies, including surveying, interviews, and tracking studies. Option 1 Contractor shall design and conduct between two (2) and six (6) rounds of formative content and experience design testing from March 2024 to December 2025. Option 2 Contractor shall design and conduct a summative evaluation of the Exhibition and companion virtual experience extending through calendar year 2024. The summative evaluation will include various methodologies, including surveying, interviews, and tracking studies. A longitudinal study may also be included to better understand what visitors remember of their experience after their visit to the museum and how/if their behaviors have changed. and how what we are developing works and how it might be improved. Alpha testing, beta At key stages of the development of the project, the contractor shall test prototypes and components under development with representative samples of the target audiences with the goal of seeing if testing, UX and UI testing also fits in this stage, dependent on the types of components being evaluated. Option 3 Contractor shall design and conduct formative testing of Exhibition title, taglines, and key branding materials (logo, title lock up, key graphics, etc.). D. Deliverables and Submittals NASA has set specific requirements for the contractor to deliver several items for the base contract. These items include a project schedule, an evaluation plan, data collection, analysis, reporting of results, and a complete database of raw data. The project schedule should identify milestones, responsibilities, and how deliverables for the project will be met. The contractor should include at least one week for each NASA review of relevant materials for key deliverables. For the evaluation plan, NASA expects the contractor to use appropriate methods that allow for outcomes to be related to specific experiences and innovations proposed in the Exhibition. NASA welcomes innovative and novel evaluative methodologies. The contractor should compare the effectiveness of different experiences in reaching the project's stated outcomes where possible. The plan should demonstrate innovative approaches appropriate for the evaluation of innovative experiences. The evaluation plan should also include the overall approach and methods to be used, types of instruments, sample size, selection, and participant recruitment, timeline/schedule for evaluation, data collection, and analysis. Additionally, the contractor must complete relevant components of the application for approval of the study from the Smithsonian Institutional Review Board and Privacy Review Board, as well as necessary NASA Internal Review Board requirements. NASA expects the final design of the Exhibition to be the result of an iterative process of development and review that involves diverse stakeholders including NASA communications teams, subject matter experts, NMNH staff, and vendors. The evaluation plan might change over the life of the project, and the contractor is expected to be flexible and adapt to the changing needs of the project. The data collection must use processes, instruments, and methods approved by NMNH and NASA COTR that carry out the proposed and approved evaluation plan. The contractor should complete data collection with sufficient time for data analysis and reporting according to the evaluation plan and schedule. The analysis of data collected as part of the evaluation study should address the outcomes identified. The contractor must complete data analysis with sufficient time for data reporting according to the evaluation plan and schedule. The reporting of preliminary and final results should provide NASA with key findings and recommendations, along with tools for communicating the findings. The contractor should use well-designed data visualizations, infographics, and presentation tools to communicate findings at-a-glance. The contractor should report findings in ways that are useful, actionable, and readable by a range of stakeholders. The contractor shall deliver dashboards, data visualization, key findings, and recommendations with sufficient time according to the evaluation plan and schedule. The final database of all raw data collected should include a coding reference guide for the database. The contractor will deliver this to the project’s contracting officer’s technical representative along with the reporting of final results. E. Specifications • • Describe target audiences’ interest in, attitudes towards, and preferences for personalization and localization of the Exhibition. • o The items developed and designed in subsequent exhibit design phases (35% and 65%) will be informed by the results of the formative evaluation. Therefore, we are interested in a quick turn-around time for data reports so that the exhibition development team can actively incorporate the information and recommendations into the exhibition plans. The evaluation findings and reports shall provide stakeholders with data, analysis, and conclusions that: Describe target audiences’ interest in, attitudes toward, and understanding of themes planned for the Exhibition. Inform the successful development of: Interactive elements and narrative approaches that are effective tools for audience engagement A particular tone or voice in the Exhibition o o • The evaluation should introduce novel approaches to evaluation that match the novel approaches we are taking to learning. For example, the evaluation could deploy new combinations of methods, new instruments, new ways to recruit and engage audiences in evaluation, and/or new ways of reporting. The evaluation should be part of the innovative culture of the Exhibition project by balancing a systematic and defensible approach to data collection and analysis with demonstrating innovation in evaluation of audience engagement and impact. NASA will furnish the following to the contractor upon request: • Content and vision documents that define the goals and objectives of the Exhibition • Access to project experts as needed to support the contractor’s work, NASA will coordinate with the museum to provide the following as needed: • Access to public gallery space and meeting space for conducting agreed-upon, scheduled data collection activities. • Access to working with content developers and exhibition designers | D16: =LEN(B16) -> 11127 | E16: Red = too long
A17: ESTIMATED COST RANGE | B17: 250000 | D17: Estimate if not on RFQ
A18: PERIOD OF PERFORMANCE | B18: 8 months | D18: Estimate if not on RFQ
A19: PLACE OF PERFORMANCE | B19: both in-person at the National Museum of Natural History, Washington, DC, USA, and virtually via Teams or other client-approved virtual meeting platforms | D19: From RFQ
A20: EVALUATION FACTORS | B20: 1. Formative evaluation approach: The Offeror shall describe its approach and ability to conduct formative evaluations both on-site and via virtual platforms. Approach shall describe representative audience selection and recruitment, test methodologies, qualitative and quantitative metrics to be used, and reporting and recommendation practices. 2. Summative evaluation approach: The Offeror shall describe its approach and ability to conduct summative evaluations both on-site and via virtual platforms. Approach shall describe representative audience selection and recruitment, test methodologies, qualitative and quantitative metrics to be used, and reporting and recommendation practices. 3. Technical Experience: The Offeror shall describe its understanding of and experience working with museum audiences and communicating complex ideas. Technical experience much include large data visualizations, virtual user engagement, and storytelling and personal narratives through the lens of earth science communication. 4. Subject matter expert availability: The Offeror shall describe its ability to obtain subject matter experts aligned with the technical area and provide availability of key personnel. 5. Past performance: The Offeror shall provide relevant experience and past performance in developing similar audience and content evaluation. Substantive evidence of successful participation in similar developments should be included which describes quantity of prior work, methodology, scope and complexity, and quality of deliverables. | D20: From RFQ
A21: INSTRUCTIONS FOR OFFERORS | B21: Quotes for the item(s) described in the RFQ are due by 4/28/2023 by 8:00 a.m. CT to Cody Guidry at cody.d.guidry@nasa.gov in order to be considered for award. If it is in the best interest of the Government, quotes submitted after the due date may be accepted. Quotes shall remain valid for 30 days unless otherwise expressly stated on the quote. Submitted Quotes shall list two points of contacts including name, phone number, and email address. All contractual and technical questions must be in writing (e-mail) to Cody Guidry at cody.d.guidry@nasa.gov no later than 4/27/2023 by 8:00 a.m. CT. Telephone questions shall not be accepted. The NAICS Code for this procurement is 541910. This procurement is set aside for small business. Offeror's shall be registered at www.sam.gov in order to be considered for award. Delivery is FOB Destination Provide your company's SAM Unique Entity ID on the submitted proposal. | D21: From RFQ
A22: POC | B22: Cody Guidry at cody.d.guidry@nasa.gov | D22: From RFQ
B23: HOW TO USE THIS TOOL:
B24: YT LINK

Sheet TECH APPROACH
A1: Chat GPT Prompt for TECH APPROACH
A3: ="Act as a copywriter for " & INPUTS!B2 & ", a Contractor preparing a Federal Proposal to provide " & INPUTS!B13 & " for " & INPUTS!B11 & " to perform " & INPUTS!B15 & ". The Basis for Award will be for the " & INPUTS!B12 & ". The Contractor Past performance includes " & INPUTS!B9 & ". The Contractor has " & INPUTS!B7 & " employees and " & INPUTS!B6 & " years of corporate experience. The Contractor " & INPUTS!B8 & "." -> Act as a copywriter for Bradford Starke, a Contractor preparing a Federal Proposal to provide Services for NASA to perform Audience Research and Evaluation for the Earth Information Center Exhibition. The Basis for Award will be for the Best Value. The Contractor Past performance includes . The Contractor has 1 employees and 4 years of corporate experience. The Contractor uses Subcontractors.
A4: ="Here is a little bit about the company: " & INPUTS!B5 -> Here is a little bit about the company: We help leaders achieve their goals through effective communications. Our team of experts combines experience and creativity to develop and execute custom strategies that accelerate success. We help leaders achieve their goals through effective communications. Our team of experts combines experience and creativity to develop and execute custom strategies that accelerate success. AWL Strategies supports a diverse list of clients, from start-ups to largefirms,non-profits,stateand local government, and Federal agencies. We are a GSA MAS contract holder and a certified Woman Owned Small Business in the following NAICS codes: 541611, 541613, 541820, 541511, 541990, 541990,561920. Marketing and Branding We align your business goals with branding and marketing goals to help you build credibility and trust with employees, customers, and strategic partners. Because leaders have their own personal brands to maintain, we provide coaching and content to help your voice and values resonate. Strategic Communications The internal is external, and vice versa. Your employees, partners and customers all want one thing: a story they can stand behind and stand for. We build strategies that start with purpose, not tactics-and drive outcomes, not just activities.
A5: Use these Section titles to structure the Proposal:
A6: A. Introduction
A7: B. Problem Statement
A8: C. Proposed Solution
A9: D. Implementation Plan
A10: E. Technical Compliance
A11: F. Past Performance: INSERT
A12: G. Quality Assurance
A13: H. Subcontractors and Partners
A14: I. Risk Management
A15: J. Cost Proposal: INSERT
A16: Write in Paragraph format primarily. Use bulletpoints when helpful, but very sparingly. Give ideas for diagrams and visuals to make Proposal more visually engaging. For the Proposed Solution: Describe your proposed solution in detail, including the technical methodology, tools, techniques, and processes you plan to employ. Explain why your approach is unique, innovative, or superior to other solutions. Prompt to INSERT past performance details and give guidance on the best types to use. For the Cost Proposal give guidance on how to keep to a competitiverange on this project and prompt them to insert the details.
A17: ="This project is to provide " & INPUTS!B13 & " under NAICS Code " & INPUTS!B14 &". ESTIMATED COST RANGE is " & INPUTS!B17 & "PERIOD OF PERFORMANCE is " & INPUTS!B18 & ". PLACE OF PERFORMANCE is " & INPUTS!B19 & ". EVALUATION FACTORS are " & INPUTS!B20 -> This project is to provide Services under NAICS Code 541910. ESTIMATED COST RANGE is 250000PERIOD OF PERFORMANCE is 8 months. PLACE OF PERFORMANCE is both in-person at the National Museum of Natural History, Washington, DC, USA, and virtually via Teams or other client-approved virtual meeting platforms. EVALUATION FACTORS are 1. Formative evaluation approach: The Offeror shall describe its approach and ability to conduct formative evaluations both on-site and via virtual platforms. Approach shall describe representative audience selection and recruitment, test methodologies, qualitative and quantitative metrics to be used, and reporting and recommendation practices. 2. Summative evaluation approach: The Offeror shall describe its approach and ability to conduct summative evaluations both on-site and via virtual platforms. Approach shall describe representative audience selection and recruitment, test methodologies, qualitative and quantitative metrics to be used, and reporting and recommendation practices. 3. Technical Experience: The Offeror shall describe its understanding of and experience working with museum audiences and communicating complex ideas. Technical experience much include large data visualizations, virtual user engagement, and storytelling and personal narratives through the lens of earth science communication. 4. Subject matter expert availability: The Offeror shall describe its ability to obtain subject matter experts aligned with the technical area and provide availability of key personnel. 5. Past performance: The Offeror shall provide relevant experience and past performance in developing similar audience and content evaluation. Substantive evidence of successful participation in similar developments should be included which describes quantity of prior work, methodology, scope and complexity, and quality of deliverables.
A18: ="Write the Technical aspects of the proposal in response to the Scope of Work: " & INPUTS!B16 -> Write the Technical aspects of the proposal in response to the Scope of Work: A. Introduction NASA Earth Science Division and National Museum of Natural History Partnership NASA Earth Science Division (ESD) maintains an extensive fleet of observing systems to collect global environmental data about the planet. ESD supports research with this data and associated models to characterize changes, understand trends, and improve predictions about the atmosphere, oceans, cryosphere, and land. ESD also supports direct applications of the data to improve decisions across a range of fields, such as water resources, agriculture, health, ecosystems management, and disasters. The Smithsonian’s National Museum of Natural History (NMNH), located on the National Mall in Washington, DC, is the most-visited natural history museum in the world with between 4 and 5 million on-site visitors and about 16 million online visitors annually. Its mission is “to better understand the natural world and our place in it.” The museum is regarded as a global leader in natural history collections, collections-based research, scientific discovery, and natural history exhibition. B. Scope of Work NASA envisions engaging with museum visitors – both on- and off-site – in new and innovative ways on this Exhibition. Audience research and evaluation will provide opportunities to test exhibition concepts and prototypes with visitors. A temporary exhibition space will include opportunities for testing content, engaging the public, and highlighting the exhibition development process. Efforts to talk with youth and their trusted adults should include, but reach beyond random sampling of individual, free-choice, on-site visitors in the galleries. Methods, such as creating focus groups of representatives of these audiences and reaching out to those organizations who organize youth tours or work with youth in community, may be considered. The contractor shall extend NASA’s reach and recruit participants and understand data that we do not have access to. The contractor shall include in their proposed plan and budget any incentives for those participating in the studies. The contractor shall provide professional, technical, and non-personal services to develop an audience research and evaluation plan for The EIC Exhibition. The execution of formative evaluation from July 2023 through summative evaluation by end of 2024 will be awarded as options as outlined below to be exercised pending funding and project scope evolution. Evaluation instruments, protocol, and appropriate incentives shall be developed by the contractor in collaboration with and approved by both NASA and NMNH. Both parties expect that the protocol required will depend on the elements being evaluated at each phase. For all evaluations design instruments will gather demographic data, including age, gender, racial/ethnic identification, and social composition of the visitor group. Throughout the implementation process, NASA will use the data, insights, and recommendations to inform decisions and adjust content to best meet the needs of the target audiences and actualize the project goals. NASA also plans to communicate salient findings from the audience research to stakeholders including NMNH leadership, NASA leadership, and the science community on a periodic basis. C. Tasks The contractor shall meet with the NASA Contracting Officer’s Technical Representative (COTR) designated in the contract and the NMNH project team, at a mutually convenient time within one week of the contract being awarded to discuss project goals, scheduling, audience research strategy, NASA/NMNH requirements (such as Human Subjects Research certification, Protection of Minors training, Internal Review Board and Privacy reviews), and NASA support. This work shall be divided into phases of work to be completed by the contractor in consultation with NASA. Throughout each phase of the contract, the contractor shall meet with the NASA COTR and/or team on at least a bi-weekly basis to determine next steps, coordinate work, and discuss interim findings. Base Contract Contractor shall create an evaluation plan and schedule for front-end and formative evaluation to support the Exhibition and companion virtual experience. Contactor shall design and conduct front-end and formative evaluation that includes target audience focus groups held online and on-site from July 2023 through November 2023 to provide baseline information about our target audiences, evaluate narrative and conceptual approaches, and prototype experience designs. Contractor shall design and conduct a summative evaluation of the Exhibition and companion virtual experience from December 2023 through February 2024. The summative evaluation will include various methodologies, including surveying, interviews, and tracking studies. Option 1 Contractor shall design and conduct between two (2) and six (6) rounds of formative content and experience design testing from March 2024 to December 2025. Option 2 Contractor shall design and conduct a summative evaluation of the Exhibition and companion virtual experience extending through calendar year 2024. The summative evaluation will include various methodologies, including surveying, interviews, and tracking studies. A longitudinal study may also be included to better understand what visitors remember of their experience after their visit to the museum and how/if their behaviors have changed. and how what we are developing works and how it might be improved. Alpha testing, beta At key stages of the development of the project, the contractor shall test prototypes and components under development with representative samples of the target audiences with the goal of seeing if testing, UX and UI testing also fits in this stage, dependent on the types of components being evaluated. Option 3 Contractor shall design and conduct formative testing of Exhibition title, taglines, and key branding materials (logo, title lock up, key graphics, etc.). D. Deliverables and Submittals NASA has set specific requirements for the contractor to deliver several items for the base contract. These items include a project schedule, an evaluation plan, data collection, analysis, reporting of results, and a complete database of raw data. The project schedule should identify milestones, responsibilities, and how deliverables for the project will be met. The contractor should include at least one week for each NASA review of relevant materials for key deliverables. For the evaluation plan, NASA expects the contractor to use appropriate methods that allow for outcomes to be related to specific experiences and innovations proposed in the Exhibition. NASA welcomes innovative and novel evaluative methodologies. The contractor should compare the effectiveness of different experiences in reaching the project's stated outcomes where possible. The plan should demonstrate innovative approaches appropriate for the evaluation of innovative experiences. The evaluation plan should also include the overall approach and methods to be used, types of instruments, sample size, selection, and participant recruitment, timeline/schedule for evaluation, data collection, and analysis. Additionally, the contractor must complete relevant components of the application for approval of the study from the Smithsonian Institutional Review Board and Privacy Review Board, as well as necessary NASA Internal Review Board requirements. NASA expects the final design of the Exhibition to be the result of an iterative process of development and review that involves diverse stakeholders including NASA communications teams, subject matter experts, NMNH staff, and vendors. The evaluation plan might change over the life of the project, and the contractor is expected to be flexible and adapt to the changing needs of the project. The data collection must use processes, instruments, and methods approved by NMNH and NASA COTR that carry out the proposed and approved evaluation plan. The contractor should complete data collection with sufficient time for data analysis and reporting according to the evaluation plan and schedule. The analysis of data collected as part of the evaluation study should address the outcomes identified. The contractor must complete data analysis with sufficient time for data reporting according to the evaluation plan and schedule. The reporting of preliminary and final results should provide NASA with key findings and recommendations, along with tools for communicating the findings. The contractor should use well-designed data visualizations, infographics, and presentation tools to communicate findings at-a-glance. The contractor should report findings in ways that are useful, actionable, and readable by a range of stakeholders. The contractor shall deliver dashboards, data visualization, key findings, and recommendations with sufficient time according to the evaluation plan and schedule. The final database of all raw data collected should include a coding reference guide for the database. The contractor will deliver this to the project’s contracting officer’s technical representative along with the reporting of final results. E. Specifications • • Describe target audiences’ interest in, attitudes towards, and preferences for personalization and localization of the Exhibition. • o The items developed and designed in subsequent exhibit design phases (35% and 65%) will be informed by the results of the formative evaluation. Therefore, we are interested in a quick turn-around time for data reports so that the exhibition development team can actively incorporate the information and recommendations into the exhibition plans. The evaluation findings and reports shall provide stakeholders with data, analysis, and conclusions that: Describe target audiences’ interest in, attitudes toward, and understanding of themes planned for the Exhibition. Inform the successful development of: Interactive elements and narrative approaches that are effective tools for audience engagement A particular tone or voice in the Exhibition o o • The evaluation should introduce novel approaches to evaluation that match the novel approaches we are taking to learning. For example, the evaluation could deploy new combinations of methods, new instruments, new ways to recruit and engage audiences in evaluation, and/or new ways of reporting. The evaluation should be part of the innovative culture of the Exhibition project by balancing a systematic and defensible approach to data collection and analysis with demonstrating innovation in evaluation of audience engagement and impact. NASA will furnish the following to the contractor upon request: • Content and vision documents that define the goals and objectives of the Exhibition • Access to project experts as needed to support the contractor’s work, NASA will coordinate with the museum to provide the following as needed: • Access to public gallery space and meeting space for conducting agreed-upon, scheduled data collection activities. • Access to working with content developers and exhibition designers
A20: Ask ChatGPT to elaborate on any areas you feel ar lacking (like Project schedule. Or, ask for a small build just to fill in details. Examples:
A22: build a likely project schedule with 5-10 bullets and short descriptions
A24: re-write the Methodology section to include more details. Put them into bullet points.

Sheet STRATEGY
A1: COMING SOON ...
A3: ="Act as a copywriter for a " & INPUTS!B15 & " / " & INPUTS!#REF! & " writing a government proposal for a company named " &INPUTS!B2 & ". Build a professional and detailed Quality Control write up." -> #ERROR!
A4: ="The company offers " & INPUTS!B13 &" including " & INPUTS!B15 -> The company offers Services including Audience Research and Evaluation for the Earth Information Center Exhibition
A5: ="The company " & INPUTS!B8 & "." -> The company uses Subcontractors.
A6: ="The company has " & INPUTS!B6 & " years of corporate experience." -> The company has 4 years of corporate experience.
A7: ="The company has " & INPUTS!B7 & " Employees." -> The company has 1 Employees.
A8: ="The company uses " & INPUTS!B16 & " for its Accounting Software." -> The company uses A. Introduction NASA Earth Science Division and National Museum of Natural History Partnership NASA Earth Science Division (ESD) maintains an extensive fleet of observing systems to collect global environmental data about the planet. ESD supports research with this data and associated models to characterize changes, understand trends, and improve predictions about the atmosphere, oceans, cryosphere, and land. ESD also supports direct applications of the data to improve decisions across a range of fields, such as water resources, agriculture, health, ecosystems management, and disasters. The Smithsonian’s National Museum of Natural History (NMNH), located on the National Mall in Washington, DC, is the most-visited natural history museum in the world with between 4 and 5 million on-site visitors and about 16 million online visitors annually. Its mission is “to better understand the natural world and our place in it.” The museum is regarded as a global leader in natural history collections, collections-based research, scientific discovery, and natural history exhibition. B. Scope of Work NASA envisions engaging with museum visitors – both on- and off-site – in new and innovative ways on this Exhibition. Audience research and evaluation will provide opportunities to test exhibition concepts and prototypes with visitors. A temporary exhibition space will include opportunities for testing content, engaging the public, and highlighting the exhibition development process. Efforts to talk with youth and their trusted adults should include, but reach beyond random sampling of individual, free-choice, on-site visitors in the galleries. Methods, such as creating focus groups of representatives of these audiences and reaching out to those organizations who organize youth tours or work with youth in community, may be considered. The contractor shall extend NASA’s reach and recruit participants and understand data that we do not have access to. The contractor shall include in their proposed plan and budget any incentives for those participating in the studies. The contractor shall provide professional, technical, and non-personal services to develop an audience research and evaluation plan for The EIC Exhibition. The execution of formative evaluation from July 2023 through summative evaluation by end of 2024 will be awarded as options as outlined below to be exercised pending funding and project scope evolution. Evaluation instruments, protocol, and appropriate incentives shall be developed by the contractor in collaboration with and approved by both NASA and NMNH. Both parties expect that the protocol required will depend on the elements being evaluated at each phase. For all evaluations design instruments will gather demographic data, including age, gender, racial/ethnic identification, and social composition of the visitor group. Throughout the implementation process, NASA will use the data, insights, and recommendations to inform decisions and adjust content to best meet the needs of the target audiences and actualize the project goals. NASA also plans to communicate salient findings from the audience research to stakeholders including NMNH leadership, NASA leadership, and the science community on a periodic basis. C. Tasks The contractor shall meet with the NASA Contracting Officer’s Technical Representative (COTR) designated in the contract and the NMNH project team, at a mutually convenient time within one week of the contract being awarded to discuss project goals, scheduling, audience research strategy, NASA/NMNH requirements (such as Human Subjects Research certification, Protection of Minors training, Internal Review Board and Privacy reviews), and NASA support. This work shall be divided into phases of work to be completed by the contractor in consultation with NASA. Throughout each phase of the contract, the contractor shall meet with the NASA COTR and/or team on at least a bi-weekly basis to determine next steps, coordinate work, and discuss interim findings. Base Contract Contractor shall create an evaluation plan and schedule for front-end and formative evaluation to support the Exhibition and companion virtual experience. Contactor shall design and conduct front-end and formative evaluation that includes target audience focus groups held online and on-site from July 2023 through November 2023 to provide baseline information about our target audiences, evaluate narrative and conceptual approaches, and prototype experience designs. Contractor shall design and conduct a summative evaluation of the Exhibition and companion virtual experience from December 2023 through February 2024. The summative evaluation will include various methodologies, including surveying, interviews, and tracking studies. Option 1 Contractor shall design and conduct between two (2) and six (6) rounds of formative content and experience design testing from March 2024 to December 2025. Option 2 Contractor shall design and conduct a summative evaluation of the Exhibition and companion virtual experience extending through calendar year 2024. The summative evaluation will include various methodologies, including surveying, interviews, and tracking studies. A longitudinal study may also be included to better understand what visitors remember of their experience after their visit to the museum and how/if their behaviors have changed. and how what we are developing works and how it might be improved. Alpha testing, beta At key stages of the development of the project, the contractor shall test prototypes and components under development with representative samples of the target audiences with the goal of seeing if testing, UX and UI testing also fits in this stage, dependent on the types of components being evaluated. Option 3 Contractor shall design and conduct formative testing of Exhibition title, taglines, and key branding materials (logo, title lock up, key graphics, etc.). D. Deliverables and Submittals NASA has set specific requirements for the contractor to deliver several items for the base contract. These items include a project schedule, an evaluation plan, data collection, analysis, reporting of results, and a complete database of raw data. The project schedule should identify milestones, responsibilities, and how deliverables for the project will be met. The contractor should include at least one week for each NASA review of relevant materials for key deliverables. For the evaluation plan, NASA expects the contractor to use appropriate methods that allow for outcomes to be related to specific experiences and innovations proposed in the Exhibition. NASA welcomes innovative and novel evaluative methodologies. The contractor should compare the effectiveness of different experiences in reaching the project's stated outcomes where possible. The plan should demonstrate innovative approaches appropriate for the evaluation of innovative experiences. The evaluation plan should also include the overall approach and methods to be used, types of instruments, sample size, selection, and participant recruitment, timeline/schedule for evaluation, data collection, and analysis. Additionally, the contractor must complete relevant components of the application for approval of the study from the Smithsonian Institutional Review Board and Privacy Review Board, as well as necessary NASA Internal Review Board requirements. NASA expects the final design of the Exhibition to be the result of an iterative process of development and review that involves diverse stakeholders including NASA communications teams, subject matter experts, NMNH staff, and vendors. The evaluation plan might change over the life of the project, and the contractor is expected to be flexible and adapt to the changing needs of the project. The data collection must use processes, instruments, and methods approved by NMNH and NASA COTR that carry out the proposed and approved evaluation plan. The contractor should complete data collection with sufficient time for data analysis and reporting according to the evaluation plan and schedule. The analysis of data collected as part of the evaluation study should address the outcomes identified. The contractor must complete data analysis with sufficient time for data reporting according to the evaluation plan and schedule. The reporting of preliminary and final results should provide NASA with key findings and recommendations, along with tools for communicating the findings. The contractor should use well-designed data visualizations, infographics, and presentation tools to communicate findings at-a-glance. The contractor should report findings in ways that are useful, actionable, and readable by a range of stakeholders. The contractor shall deliver dashboards, data visualization, key findings, and recommendations with sufficient time according to the evaluation plan and schedule. The final database of all raw data collected should include a coding reference guide for the database. The contractor will deliver this to the project’s contracting officer’s technical representative along with the reporting of final results. E. Specifications • • Describe target audiences’ interest in, attitudes towards, and preferences for personalization and localization of the Exhibition. • o The items developed and designed in subsequent exhibit design phases (35% and 65%) will be informed by the results of the formative evaluation. Therefore, we are interested in a quick turn-around time for data reports so that the exhibition development team can actively incorporate the information and recommendations into the exhibition plans. The evaluation findings and reports shall provide stakeholders with data, analysis, and conclusions that: Describe target audiences’ interest in, attitudes toward, and understanding of themes planned for the Exhibition. Inform the successful development of: Interactive elements and narrative approaches that are effective tools for audience engagement A particular tone or voice in the Exhibition o o • The evaluation should introduce novel approaches to evaluation that match the novel approaches we are taking to learning. For example, the evaluation could deploy new combinations of methods, new instruments, new ways to recruit and engage audiences in evaluation, and/or new ways of reporting. The evaluation should be part of the innovative culture of the Exhibition project by balancing a systematic and defensible approach to data collection and analysis with demonstrating innovation in evaluation of audience engagement and impact. NASA will furnish the following to the contractor upon request: • Content and vision documents that define the goals and objectives of the Exhibition • Access to project experts as needed to support the contractor’s work, NASA will coordinate with the museum to provide the following as needed: • Access to public gallery space and meeting space for conducting agreed-upon, scheduled data collection activities. • Access to working with content developers and exhibition designers for its Accounting Software.
A9: ="The company has the following customers and customer types: " & INPUTS!B12 -> The company has the following customers and customer types: Best Value
A10: ="Here is a little bit about the company: " & INPUTS!B5 -> Here is a little bit about the company: We help leaders achieve their goals through effective communications. Our team of experts combines experience and creativity to develop and execute custom strategies that accelerate success. We help leaders achieve their goals through effective communications. Our team of experts combines experience and creativity to develop and execute custom strategies that accelerate success. AWL Strategies supports a diverse list of clients, from start-ups to largefirms,non-profits,stateand local government, and Federal agencies. We are a GSA MAS contract holder and a certified Woman Owned Small Business in the following NAICS codes: 541611, 541613, 541820, 541511, 541990, 541990,561920. Marketing and Branding We align your business goals with branding and marketing goals to help you build credibility and trust with employees, customers, and strategic partners. Because leaders have their own personal brands to maintain, we provide coaching and content to help your voice and values resonate. Strategic Communications The internal is external, and vice versa. Your employees, partners and customers all want one thing: a story they can stand behind and stand for. We build strategies that start with purpose, not tactics-and drive outcomes, not just activities.
A11: Use these Section titles to structure the Proposal:
A12: (A) Description of internal review procedures that facilitate high-quality standards.
A13: (B) Identification of individuals responsible for ensuring quality control. (INSERT MANUALLY)
A14: (C) Whether or not subcontractors are used and, if so, the quality control measures used to ensure acceptable subcontractor performance.
A15: (D) How potential problem areas and solutions are handled ?
A16: (E) The procedures for ensuring quality performance when meeting urgent requirements.
A17: (F) How quality control will be managed when completing multiple projects for multiple agencies simultaneously.
A18: ="Keywords to use: "&INPUTS!#REF!&" , "&INPUTS!B17&" , "&INPUTS!#REF!&" , "&INPUTS!#REF!&" , "&INPUTS!#REF! -> #ERROR!
A19: Write in Paragraph format primarily. Use bulletpoints when helpful, but very sparingly. Give ideas for diagrams and visuals to make Proposal more visually engaging.
A22: Ask ChatGPT to elaborate on any areas you feel ar lacking. Or, ask for a small build just to fill in details.

Sheet EXEC SUMMARY
A1: COMING SOON ...
A3: ="Act as a copywriter for a " & INPUTS!B15 & " / " & INPUTS!#REF! & " writing a government proposal for a company named " &INPUTS!B2 & ". Build a professional and detailed Corporate experience write up." -> #ERROR!
A4: ="The company offers " & INPUTS!B13 &" including " & INPUTS!B15 -> The company offers Services including Audience Research and Evaluation for the Earth Information Center Exhibition
A5: ="The company " & INPUTS!B8 & "." -> The company uses Subcontractors.
A6: ="The company has " & INPUTS!B6 & " years of corporate experience." -> The company has 4 years of corporate experience.
A7: ="The company has " & INPUTS!B7 & " Employees." -> The company has 1 Employees.
A8: ="The company uses " & INPUTS!B16 & " for its Accounting Software." -> The company uses A. Introduction NASA Earth Science Division and National Museum of Natural History Partnership NASA Earth Science Division (ESD) maintains an extensive fleet of observing systems to collect global environmental data about the planet. ESD supports research with this data and associated models to characterize changes, understand trends, and improve predictions about the atmosphere, oceans, cryosphere, and land. ESD also supports direct applications of the data to improve decisions across a range of fields, such as water resources, agriculture, health, ecosystems management, and disasters. The Smithsonian’s National Museum of Natural History (NMNH), located on the National Mall in Washington, DC, is the most-visited natural history museum in the world with between 4 and 5 million on-site visitors and about 16 million online visitors annually. Its mission is “to better understand the natural world and our place in it.” The museum is regarded as a global leader in natural history collections, collections-based research, scientific discovery, and natural history exhibition. B. Scope of Work NASA envisions engaging with museum visitors – both on- and off-site – in new and innovative ways on this Exhibition. Audience research and evaluation will provide opportunities to test exhibition concepts and prototypes with visitors. A temporary exhibition space will include opportunities for testing content, engaging the public, and highlighting the exhibition development process. Efforts to talk with youth and their trusted adults should include, but reach beyond random sampling of individual, free-choice, on-site visitors in the galleries. Methods, such as creating focus groups of representatives of these audiences and reaching out to those organizations who organize youth tours or work with youth in community, may be considered. The contractor shall extend NASA’s reach and recruit participants and understand data that we do not have access to. The contractor shall include in their proposed plan and budget any incentives for those participating in the studies. The contractor shall provide professional, technical, and non-personal services to develop an audience research and evaluation plan for The EIC Exhibition. The execution of formative evaluation from July 2023 through summative evaluation by end of 2024 will be awarded as options as outlined below to be exercised pending funding and project scope evolution. Evaluation instruments, protocol, and appropriate incentives shall be developed by the contractor in collaboration with and approved by both NASA and NMNH. Both parties expect that the protocol required will depend on the elements being evaluated at each phase. For all evaluations design instruments will gather demographic data, including age, gender, racial/ethnic identification, and social composition of the visitor group. Throughout the implementation process, NASA will use the data, insights, and recommendations to inform decisions and adjust content to best meet the needs of the target audiences and actualize the project goals. NASA also plans to communicate salient findings from the audience research to stakeholders including NMNH leadership, NASA leadership, and the science community on a periodic basis. C. Tasks The contractor shall meet with the NASA Contracting Officer’s Technical Representative (COTR) designated in the contract and the NMNH project team, at a mutually convenient time within one week of the contract being awarded to discuss project goals, scheduling, audience research strategy, NASA/NMNH requirements (such as Human Subjects Research certification, Protection of Minors training, Internal Review Board and Privacy reviews), and NASA support. This work shall be divided into phases of work to be completed by the contractor in consultation with NASA. Throughout each phase of the contract, the contractor shall meet with the NASA COTR and/or team on at least a bi-weekly basis to determine next steps, coordinate work, and discuss interim findings. Base Contract Contractor shall create an evaluation plan and schedule for front-end and formative evaluation to support the Exhibition and companion virtual experience. Contactor shall design and conduct front-end and formative evaluation that includes target audience focus groups held online and on-site from July 2023 through November 2023 to provide baseline information about our target audiences, evaluate narrative and conceptual approaches, and prototype experience designs. Contractor shall design and conduct a summative evaluation of the Exhibition and companion virtual experience from December 2023 through February 2024. The summative evaluation will include various methodologies, including surveying, interviews, and tracking studies. Option 1 Contractor shall design and conduct between two (2) and six (6) rounds of formative content and experience design testing from March 2024 to December 2025. Option 2 Contractor shall design and conduct a summative evaluation of the Exhibition and companion virtual experience extending through calendar year 2024. The summative evaluation will include various methodologies, including surveying, interviews, and tracking studies. A longitudinal study may also be included to better understand what visitors remember of their experience after their visit to the museum and how/if their behaviors have changed. and how what we are developing works and how it might be improved. Alpha testing, beta At key stages of the development of the project, the contractor shall test prototypes and components under development with representative samples of the target audiences with the goal of seeing if testing, UX and UI testing also fits in this stage, dependent on the types of components being evaluated. Option 3 Contractor shall design and conduct formative testing of Exhibition title, taglines, and key branding materials (logo, title lock up, key graphics, etc.). D. Deliverables and Submittals NASA has set specific requirements for the contractor to deliver several items for the base contract. These items include a project schedule, an evaluation plan, data collection, analysis, reporting of results, and a complete database of raw data. The project schedule should identify milestones, responsibilities, and how deliverables for the project will be met. The contractor should include at least one week for each NASA review of relevant materials for key deliverables. For the evaluation plan, NASA expects the contractor to use appropriate methods that allow for outcomes to be related to specific experiences and innovations proposed in the Exhibition. NASA welcomes innovative and novel evaluative methodologies. The contractor should compare the effectiveness of different experiences in reaching the project's stated outcomes where possible. The plan should demonstrate innovative approaches appropriate for the evaluation of innovative experiences. The evaluation plan should also include the overall approach and methods to be used, types of instruments, sample size, selection, and participant recruitment, timeline/schedule for evaluation, data collection, and analysis. Additionally, the contractor must complete relevant components of the application for approval of the study from the Smithsonian Institutional Review Board and Privacy Review Board, as well as necessary NASA Internal Review Board requirements. NASA expects the final design of the Exhibition to be the result of an iterative process of development and review that involves diverse stakeholders including NASA communications teams, subject matter experts, NMNH staff, and vendors. The evaluation plan might change over the life of the project, and the contractor is expected to be flexible and adapt to the changing needs of the project. The data collection must use processes, instruments, and methods approved by NMNH and NASA COTR that carry out the proposed and approved evaluation plan. The contractor should complete data collection with sufficient time for data analysis and reporting according to the evaluation plan and schedule. The analysis of data collected as part of the evaluation study should address the outcomes identified. The contractor must complete data analysis with sufficient time for data reporting according to the evaluation plan and schedule. The reporting of preliminary and final results should provide NASA with key findings and recommendations, along with tools for communicating the findings. The contractor should use well-designed data visualizations, infographics, and presentation tools to communicate findings at-a-glance. The contractor should report findings in ways that are useful, actionable, and readable by a range of stakeholders. The contractor shall deliver dashboards, data visualization, key findings, and recommendations with sufficient time according to the evaluation plan and schedule. The final database of all raw data collected should include a coding reference guide for the database. The contractor will deliver this to the project’s contracting officer’s technical representative along with the reporting of final results. E. Specifications • • Describe target audiences’ interest in, attitudes towards, and preferences for personalization and localization of the Exhibition. • o The items developed and designed in subsequent exhibit design phases (35% and 65%) will be informed by the results of the formative evaluation. Therefore, we are interested in a quick turn-around time for data reports so that the exhibition development team can actively incorporate the information and recommendations into the exhibition plans. The evaluation findings and reports shall provide stakeholders with data, analysis, and conclusions that: Describe target audiences’ interest in, attitudes toward, and understanding of themes planned for the Exhibition. Inform the successful development of: Interactive elements and narrative approaches that are effective tools for audience engagement A particular tone or voice in the Exhibition o o • The evaluation should introduce novel approaches to evaluation that match the novel approaches we are taking to learning. For example, the evaluation could deploy new combinations of methods, new instruments, new ways to recruit and engage audiences in evaluation, and/or new ways of reporting. The evaluation should be part of the innovative culture of the Exhibition project by balancing a systematic and defensible approach to data collection and analysis with demonstrating innovation in evaluation of audience engagement and impact. NASA will furnish the following to the contractor upon request: • Content and vision documents that define the goals and objectives of the Exhibition • Access to project experts as needed to support the contractor’s work, NASA will coordinate with the museum to provide the following as needed: • Access to public gallery space and meeting space for conducting agreed-upon, scheduled data collection activities. • Access to working with content developers and exhibition designers for its Accounting Software.
A9: ="The company has the following customers and customer types: " & INPUTS!B12 -> The company has the following customers and customer types: Best Value
